2019-01-28 21:36:12,826 ERROR: Exception on /edit_profile [POST] [in c:\users\richi\projects\calisthenics-progression\cp_env\lib\site-packages\flask\app.py:1761]
Traceback (most recent call last):
  File "c:\users\richi\projects\calisthenics-progression\cp_env\lib\site-packages\flask\app.py", line 2292, in wsgi_app
    response = self.full_dispatch_request()
  File "c:\users\richi\projects\calisthenics-progression\cp_env\lib\site-packages\flask\app.py", line 1815, in full_dispatch_request
    rv = self.handle_user_exception(e)
  File "c:\users\richi\projects\calisthenics-progression\cp_env\lib\site-packages\flask\app.py", line 1718, in handle_user_exception
    reraise(exc_type, exc_value, tb)
  File "c:\users\richi\projects\calisthenics-progression\cp_env\lib\site-packages\flask\_compat.py", line 35, in reraise
    raise value
  File "c:\users\richi\projects\calisthenics-progression\cp_env\lib\site-packages\flask\app.py", line 1813, in full_dispatch_request
    rv = self.dispatch_request()
  File "c:\users\richi\projects\calisthenics-progression\cp_env\lib\site-packages\flask\app.py", line 1799, in dispatch_request
    return self.view_functions[rule.endpoint](**req.view_args)
  File "c:\users\richi\projects\calisthenics-progression\cp_env\lib\site-packages\flask_login\utils.py", line 261, in decorated_view
    return func(*args, **kwargs)
  File "C:\Users\richi\projects\calisthenics-progression\app\routes.py", line 89, in edit_profile
    if form.validate_on_submit():
  File "c:\users\richi\projects\calisthenics-progression\cp_env\lib\site-packages\flask_wtf\form.py", line 101, in validate_on_submit
    return self.is_submitted() and self.validate()
  File "c:\users\richi\projects\calisthenics-progression\cp_env\lib\site-packages\wtforms\form.py", line 310, in validate
    return super(Form, self).validate(extra)
  File "c:\users\richi\projects\calisthenics-progression\cp_env\lib\site-packages\wtforms\form.py", line 152, in validate
    if not field.validate(self, extra):
  File "c:\users\richi\projects\calisthenics-progression\cp_env\lib\site-packages\wtforms\fields\core.py", line 206, in validate
    stop_validation = self._run_validation_chain(form, chain)
  File "c:\users\richi\projects\calisthenics-progression\cp_env\lib\site-packages\wtforms\fields\core.py", line 226, in _run_validation_chain
    validator(form, self)
  File "C:\Users\richi\projects\calisthenics-progression\app\forms.py", line 42, in validate_username
    if user is not None:
UnboundLocalError: local variable 'user' referenced before assignment
2019-01-28 21:50:43,934 INFO: Calisthenics-Progression startup [in C:\Users\richi\projects\calisthenics-progression\app\__init__.py:28]
2019-01-28 21:53:07,309 INFO: Calisthenics-Progression startup [in C:\Users\richi\projects\calisthenics-progression\app\__init__.py:28]
2019-01-28 21:53:15,777 INFO: Calisthenics-Progression startup [in C:\Users\richi\projects\calisthenics-progression\app\__init__.py:28]
2019-01-28 22:08:32,831 INFO: Calisthenics-Progression startup [in C:\Users\richi\projects\calisthenics-progression\app\__init__.py:28]
2019-01-28 22:12:29,660 INFO: Calisthenics-Progression startup [in C:\Users\richi\projects\calisthenics-progression\app\__init__.py:28]
2019-01-28 22:12:47,745 INFO: Calisthenics-Progression startup [in C:\Users\richi\projects\calisthenics-progression\app\__init__.py:28]
2019-01-28 22:13:26,150 INFO: Calisthenics-Progression startup [in C:\Users\richi\projects\calisthenics-progression\app\__init__.py:28]
2019-01-28 22:20:22,456 INFO: Calisthenics-Progression startup [in C:\Users\richi\projects\calisthenics-progression\app\__init__.py:28]
